Workbook

Sheet How to Solve
A1: This describes the model notes.
A4: MODEL SOLUTION
A5: 1. Note that we have designed the runs so that a file named "Rice_{date}.xlsm" is the file in which the assumptions are
A6: embedded. This allows a common set of assumptions for all variants.
A7: Note that this uses the Baseline with damages as the calibration for utility and units.
A9: 2. The major controls are at the top of the "Controls" sheet. You can do the following:
A11: a. For the baseline, set as follows, and make sure that the "Global carbon price" in row 9 is set to .001. This is >0 to prevent numerical problems.
A12: Control = 1 if tax or 0 if capped | I12: 1
A13: Trade (0) or no trade (1) | I13: 1
A15: Be careful not to override the if statement that starts around 2150.
A16: b. For the optimal run, you need to optimize with solver. You can get a starting point by copying the "tentative optimal prices" from row 84 of "Controls" sheet.
A17: Make sure the settings at the top are:
A18: Control = 1 if tax or 0 if capped | I18: 1
A19: Trade (0) or no trade (1) | I19: 1
A22: c. For the Copenhagen runs, we set the top controls at:
A23: Control = 1 if tax or 0 if capped | D23: 1
A24: If you want FULL trading, set the second row as:
A25: Trade (0) or no trade (1) | D25: 0
A26: Note: The full trade requires optimization. You need to minimize the error in the "Global" spreadsheet at entry B115.
A27: This is done by adjusting the carbon prices for trading in row 118. This is very tricky and is best accomplished by moving slowly from left to right.
A29: d. If you want NO trading, set the second row as:
A30: Trade (0) or no trade (1) | D30: 1
A31: Note: This is calculated directly and needs no further calculations.
A33: MODEL CHANGES
A34: VERY IMPORTANT NOTE FOR USERS:
A35: 3. The model has been calibrated for the current baseline assumptions. In general there will be no problems in changing assumptions
A36: about POLICIES. However, if you change the baseline, you may run in to all kinds of calibration problems.
A37: The problems will require only modest adjustments for the baseline, optimal, and limit runs.
A38: However, the calibration for the Copenhagen runs is complicated, and users are advised that changes in these runs
A39: are likely to introduce errors.
A41: 4. The main changes that are necessary if you make parameter changes is that you will need to RENORMALIZE THE BASELINE RUN.A64
A42: Procedures for this are described below. Make sure that the renormalization is for the Baseline. DO NOT renormalize the
A43: policy runs; rather use the renormalization for the baseline as the normalization for other runs.
A45: NORMALIZATIONS AND INITIALIZATIONS
... A133: 14. Note that the utility and consumption discount rates are as follows for US, China, and India for the base case
B134: 2015 | C134: 2005-2055 | D134: 2005-2105
A135: Model real rates
A136: Utility rates | E136: 2005 | F136: 2015 | G136: 2025 | H136: 2035 | I136: 2045 | J136: 2055 | K136: 2065 | L136: 2075 | M136: 2085 | N136: 2095 | O136: 2105 | P136: 2115
A137: US | B137: 0.046980023 | C137: 0.043355523 | D137: 0.032182676 | F137: 0.046980023 | G137: 0.047203002 | H137: 0.041644592 | I137: 0.037594477 | J137: 0.034485311 | K137: 0.032592476 | L137: 0.031458552 | M137: 0.030553561 | N137: 0.029746124 | O137: 0.028848234 | P137: 0.027041372
A138: China | B138: 0.11343412 | C138: 0.068386495 | D138: 0.037861577 | F138: 0.11343412 | G138: 0.061657543 | H138: 0.05260098 | I138: 0.045853336 | J138: 0.041762666 | K138: 0.039374227 | L138: 0.037081845 | M138: 0.034525088 | N138: 0.032984987 | O138: 0.033448893 | P138: 0.034101759
...

Sheet Results
B1: 2005 | C1: 2015 | D1: 2025 | E1: 2035 | F1: 2045 | G1: 2055 | H1: 2065 | I1: 2075 | J1: 2085 | K1: 2095 | L1: 2105 | M1: 2115 | N1: 2125 | O1: 2135 | P1: 2145 | Q1: 2155 | R1: 2165 | S1: 2175 | T1: 2185 | U1: 2195 | V1: 2205 | W1: 2215 | X1: 2225 | Y1: 2235 | Z1: 2245 | AA1: 2255 | AB1: 2265 | AC1: 2275 | AD1: 2285 | AE1: 2295 | AF1: 2305 | AG1: 2315 | AH1: 2325 | AI1: 2335 | AJ1: 2345 | AK1: 2355 | AL1: 2365 | AM1: 2375 | AN1: 2385 | AO1: 2395 | AP1: 2405 | AQ1: 2415 | AR1: 2425 | AS1: 2435 | AT1: 2445 | AU1: 2455 | AV1: 2465 | AW1: 2475 | AX1: 2485 | AY1: 2495 | AZ1: 2505 | BA1: 2515 | BB1: 2525 | BC1: 2535 | BD1: 2545 | BE1: 2555 | BF1: 2565 | BG1: 2575 | BH1: 2585 | BI1: 2595 | BJ1: 2605 | BK1: 2615 | BL1: 2625 | BM1: 2635 | BN1: 2645 | BO1: 2655 | BP1: 2665 | BQ1: 2675 | BR1: 2685 | BS1: 2695 | BT1: 2705 | BU1: 2715 | BV1: 2725 | BW1: 2735 | BX1: 2745 | BY1: 2755 | BZ1: 2765 | CA1: 2775 | CB1: 2785 | CC1: 2795 | CD1: 2805 | CE1: 2815 | CF1: 2825 | CG1: 2835 | CH1: 2845 | CI1: 2855 | CJ1: 2865 | CK1: 2875 | CL1: 2885 | CM1: 2895 | CN1: 2905 | CO1: 2915 | CP1: 2925 | CQ1: 2935 | CR1: 2945 | CS1: 2955 | CT1: 2965 | CU1: 2975 | CV1: 2985 | CW1: 2995 | CX1: 3005 | CY1: 3015
B2: 0.001
A3: base utility | B3: =+Controls!B4 -> 2301.518
A4: add emissions
A5: Total carbon emissions (GTC per year) | B5: =SUM(US:OthAsia!B70)+B4 -> 9.5676364 | C5: =SUM(US:OthAsia!C70)+C4 -> 11.283554 | D5: =SUM(US:OthAsia!D70)+D4 -> 12.742375 | E5: =SUM(US:OthAsia!E70)+E4 -> 13.997138 | F5: =SUM(US:OthAsia!F70)+F4 -> 15.097383 | G5: =SUM(US:OthAsia!G70)+G4 -> 15.959184 | H5: =SUM(US:OthAsia!H70)+H4 -> 16.704702 | I5: =SUM(US:OthAsia!I70)+I4 -> 17.457585 | ... BI5: =SUM(US:OthAsia!BI70)+BI4 -> 3.0649911e-06
A6: Base utility value | B6: 1753.4878
A7: New delta utility value | B7: 1753.4876 | C7: 1753.4876 | D7: 1753.4877 | E7: 1753.4877 | F7: 1753.4877 | G7: 1753.4877 | L7: 1753.4878
A8: Correction factor | B8: 0.98484913 | C8: 1.028416 | D8: 1.1148742 | E8: 0.68942855 | F8: 0.75831031 | G8: 0.83100581 | L8: 0.866
A9: Utility discount rate | B9: =+Global!B366 -> 1 | C9: =+Global!C366 -> 0.56467664 | D9: =+Global!D366 -> 0.32827176 | E9: =+Global!F366 -> 0.12755891 | F9: =+Global!G366 -> 0.083386464 | G9: =+Global!H366 -> 0.055946662 | H9: =+Global!I366 -> 0.038321989 | I9: =+Global!J366 -> 0.026723173 | J9: =+Global!K366 -> 0.018945339 | K9: =+Global!L366 -> 0.013654215 | L9: =+Global!M366 -> 0.010096491 | ... BH9: =+Global!BI366 -> 0 | BI9: =+Global!#REF! -> #REF!
A10: PV change | B10: =100000*($B6-B7)/B9 -> 17.753654 | C10: =100000*($B6-C7)/C9 -> 28.993156 | D10: =100000*($B6-D7)/D9 -> 37.351038 | E10: =100000*($B6-E7)/E9 -> 72.282425 | F10: =100000*($B6-F7)/F9 -> 83.596518 | G10: =100000*($B6-G7)/G9 -> 94.902587 | L10: =100000*($B6-L7)/L9 -> 149.24869
A11: PV corrected | B11: =+B10*B8 -> 17.484671 | C11: =+C10*C8 -> 29.817026 | D11: =+D10*D8 -> 41.641708 | E11: =+E10*E8 -> 49.833567 | F11: =+F10*F8 -> 63.392101 | G11: =+G10*G8 -> 78.864602 | L11: =+L10*L8 -> 129.24937
A12: From tax estimates (base case) | B12: 17.48467 | C12: 32.86382 | D12: 48.723172 | E12: 68.744445 | F12: 93.800861 | G12: 124.48185 | H12: 161.24872 | I12: 204.68798 | J12: 254.94894 | K12: 311.87486 | L12: 374.22828 | M12: 831.12188
A13: From analytical | B13: =+Global!B378 -> 38.667086 | C13: =+Global!C378 -> 68.47651 | D13: =+Global!D378 -> 113.71469 | E13: =+Global!E378 -> 170.37783 | F13: =+Global!F378 -> 230.74967 | G13: =+Global!G378 -> 295.12026
A14: Run | B14: =+C14+1 -> 1004 | C14: 1003
A15: Rate of social time preference (% py) | F15: =+IF(D10>70,1,"")
A16: Elasticity of MU of consumption (set) | F16: Error from correction factor | I16: =+SUMPRODUCT(F17:K17*F17:K17) -> 0.34477945
A17: Damage coefficient on temperature | B17: =NORMINV(RAND(),0,1) -> -0.1393038 | C17: 1.3244487 | F17: =+B11/B12-1 -> 2.0491439e-08 | G17: =+C11/C12-1 -> -0.092709651 | H17: =+D11/D12-1 -> -0.14534078 | I17: =+E11/E12-1 -> -0.27508954 | J17: =+F11/F12-1 -> -0.32418423 | K17: =+G11/G12-1 -> -0.36645704
A18: Damage coefficient on temperature squared | B18: =NORMINV(RAND(),0,1) -> 1.6161299 | C18: 0.37069644 | F18: [need to estimate optimal taxes to use this]
A19: Exponent on damages | B19: =NORMINV(RAND(),0,1) -> -0.26279453 | C19: 0.25897881 | F19: =+B12/B10 -> 0.98484911 | G19: =+C12/C10 -> 1.1335027 | H19: =+D12/D10 -> 1.3044664 | I19: =+E12/E10 -> 0.95105339 | J19: =+F12/F10 -> 1.1220666 | K19: =+G12/G10 -> 1.3116803 | P19: =+L12/L10 -> 2.5074141
A20: Price backstop technology (2005 US 000 $ per tC) | B20: =NORMINV(RAND(),0,1) -> 0.30282431 | C20: -1.1981161 | E20: T(2200) | F20: =+Z62 -> 6.466549
A21: Exponent of control cost function | B21: =NORMINV(RAND(),0,1) -> -0.1650027 | C21: 0.43330179 | E21: SLR(2500) | F21: =+BB77 -> 7.7009348
A22: Backstop inflection year | B22: =NORMINV(RAND(),0,1) -> 1.1218685 | C22: 1.6502441
A23: Maximum carbon resources (GtC) | B23: =NORMINV(RAND(),0,1) -> 0.16622682 | C23: 0.55269204
A24: Equilibrium temperature increase for CO2 doubling | B24: =NORMINV(RAND(),0,1) -> -0.56548631 | C24: -0.091249155
A25: Decline rate TFP (per decade) | B25: =NORMINV(RAND(),0,1) -> -0.51388316 | C25: -1.7407395
A26: TFP convergence rate (per decade) | B26: =NORMINV(RAND(),0,1) -> 2.3301223 | C26: -0.42879277
A27: Long run growth rate (per year) | B27: =NORMINV(RAND(),0,1) -> -0.33463247 | C27: 1.9653861
A28: Decline rate sigma growth (per decade) | B28: =NORMINV(RAND(),0,1) -> -0.81814271 | C28: -1.0779841
A29: Trend sigma growth (per year) | B29: =NORMINV(RAND(),0,1) -> 2.0741159 | C29: 0.46847076
A30: Uncertainty for frontier (US) TFP | B30: =NORMINV(RAND(),0,1) -> 1.1571671 | C30: -1.0454297
A31: Adjustment rates for SLR (multiplicative) | B31: =NORMINV(RAND(),0,1) -> -1.6299691 | C31: 0.35346622
A32: Random threshold temperature for melt SLR (m) | B32: =NORMINV(RAND(),0,1) -> -2.2812446 | C32: -0.75943163
A33: Population adjustment (factor for 2200) | B33: =NORMINV(RAND(),0,1) -> -0.20131174 | C33: 1.0994498
... A36: Convergence uncertainty | B36: =NORMINV(RAND(),0,1) -> 0.74771639 | C36: 1.0148936
A37: dummy
A38: dummy
S40: =+Parameters!B22 -> 0.1
B42: =+Parameters!A9 -> Rate of social time preference (% py) | C42: =+Parameters!A10 -> Elasticity of MU of consumption (set) | D42: =+Parameters!A11 -> Damage coefficient on temperature | E42: =+Parameters!A12 -> Damage coefficient on temperature squared | F42: =+Parameters!A13 -> Exponent on damages | G42: =+Parameters!A14 -> Price backstop technology (2005 US 000 $ per tC) | H42: =+Parameters!A15 -> Exponent of control cost function | I42: =+Parameters!A16 -> Backstop inflection year | J42: =+Parameters!A17 -> Maximum carbon resources (GtC) | K42: =+Parameters!A18 -> Equilibrium temperature increase for CO2 doubling | L42: =+Parameters!A19 -> Decline rate TFP (per decade) | M42: =+Parameters!A20 -> TFP convergence rate (per decade) | N42: =+Parameters!A21 -> Long run growth rate (per year) | O42: =+Parameters!A22 -> Decline rate sigma growth (per decade) | P42: =+Parameters!A23 -> Trend sigma growth (per year) | Q42: =+Parameters!A24 -> Uncertainty for frontier (US) TFP | R42: =+Parameters!A25 -> Adjustment rates for SLR (multiplicative) | S42: =+Parameters!A26 -> Random threshold temperature for melt SLR (m) | T42: =+Parameters!A27 -> Population uncertainty (factor for 2200) | U42: =+Parameters!A28 -> Carbon cycle adjustment coefficient | V42: =+Parameters!A29 -> Damage rate at threshold for catastrophic damages | W42: =+Parameters!A30 -> Convergence uncertainty
B43: 2005 | C43: =+B43+10 -> 2015 | D43: =+C43+10 -> 2025 | E43: =+D43+10 -> 2035 | F43: =+E43+10 -> 2045 | G43: =+F43+10 -> 2055 | H43: =+G43+10 -> 2065 | I43: =+H43+10 -> 2075 | J43: =+I43+10 -> 2085 | ... CY43: =+CX43+10 -> 3015
A44: Parameters of uncertain variables | B44: =+Parameters!B9 -> 0.015 | C44: =+Parameters!B10 -> 1.5 | D44: =+Parameters!B11 -> 0.0017543802 | E44: =+Parameters!B12 -> 0.0022592108 | F44: =+Parameters!B13 -> 2 | G44: =+Parameters!B14 -> 1.2 | H44: =+Parameters!B15 -> 2.8 | I44: =+Parameters!B16 -> 2250 | J44: =+Parameters!B17 -> 6000 | K44: =+Parameters!B18 -> 3.2 | L44: =+Parameters!B19 -> 0.1 | M44: =+Parameters!B20 -> 0.1 | N44: =+Parameters!B21 -> 0.0033 | O44: =+Parameters!B22 -> 0.1 | P44: =+Parameters!B23 -> -0.0025 | Q44: =+Parameters!B24 -> 0 | R44: =+Parameters!B25 -> 1 | S44: =+Parameters!B26 -> 0 | T44: =+Parameters!B27 -> 1 | U44: =+Parameters!B28 -> 12 | V44: =+Parameters!B29 -> 0 | W44: =+Parameters!B30 -> 0
...

Sheet Controls
A1: OBJECTIVE FUNCTION TO BE MAXIMIZED | C1: Control = 1 if tax or 0 if capped | I1: 1
A2: Welfare with International Weights | C2: Trade (0) or no trade (1) | I2: 1
A4: Sum of utilities (trillions of 2005 US$) | B4: =SUM(US:OthAsia!B95) -> 2301.518 | C4: 2301.518 | D4: =+B4-C4 -> 0
B5: 1 | C5: 2 | D5: 3 | E5: 4 | F5: 5 | G5: 6 | H5: 7 | I5: 8 | J5: 9 | K5: 10 | L5: 11 | M5: 12 | N5: 13 | O5: 14 | P5: 15 | Q5: 16 | R5: 17 | S5: 18 | T5: 19 | U5: 20 | V5: 21 | W5: 22 | X5: 23 | Y5: 24 | Z5: 25 | AA5: 26 | AB5: 27 | AC5: 28 | AD5: 29 | AE5: 30 | AF5: 31 | AG5: 32 | AH5: 33 | AI5: 34 | AJ5: 35 | AK5: 36 | AL5: 37 | AM5: 38 | AN5: 39 | AO5: 40 | AP5: 41 | AQ5: 42 | AR5: 43 | AS5: 44 | AT5: 45 | AU5: 46 | AV5: 47 | AW5: 48 | AX5: 49 | AY5: 50 | AZ5: 51 | BA5: 52 | BB5: 53 | BC5: 54 | BD5: 55 | BE5: 56 | BF5: 57 | BG5: 58 | BH5: 59 | BI5: 60
B6: 2005 | C6: 2015 | D6: 2025 | E6: 2035 | F6: 2045 | G6: 2055 | H6: 2065 | I6: 2075 | J6: 2085 | K6: 2095 | L6: 2105 | M6: 2115 | N6: 2125 | O6: 2135 | P6: 2145 | Q6: 2155 | R6: 2165 | S6: 2175 | T6: 2185 | U6: 2195 | V6: 2205 | W6: 2215 | X6: 2225 | Y6: 2235 | Z6: 2245 | AA6: 2255 | AB6: 2265 | AC6: 2275 | AD6: 2285 | AE6: 2295 | AF6: 2305 | AG6: 2315 | AH6: 2325 | AI6: 2335 | AJ6: 2345 | AK6: 2355 | AL6: 2365 | AM6: 2375 | AN6: 2385 | AO6: 2395 | AP6: 2405 | AQ6: 2415 | AR6: 2425 | AS6: 2435 | AT6: 2445 | AU6: 2455 | AV6: 2465 | AW6: 2475 | AX6: 2485 | AY6: 2495 | AZ6: 2505 | BA6: 2515 | BB6: 2525 | BC6: 2535 | BD6: 2545 | BE6: 2555 | BF6: 2565 | BG6: 2575 | BH6: 2585 | BI6: 2595
A7: CARBON TAX CONTROL VARIABLE | C7: 0
A8: Carbon tax (2005 US$ per ton C) | B8: =+B9+B10 -> 0.001 | C8: =+C9+C10 -> 0.001 | D8: =+D9+D10 -> 0.001 | E8: =+E9+E10 -> 0.001 | F8: =+F9+F10 -> 0.001 | G8: =+G9+G10 -> 0.0010000001 | H8: =+H9+H10 -> 0.001000001 | I8: =+I9+I10 -> 0.0010000114 | ... Z8: =+Z9+Z10 -> 5.6313005 | AA8: =+MIN(AA9+AA10,Global!AA81) -> 10.591311 | AB8: =+MIN(AB9+AB10,Global!AB81) -> 102.851 | AC8: =+MIN(AC9+AC10,Global!AC81) -> 51.4255 | AD8: =+MIN(AD9+AD10,Global!AD81) -> 25.71275 | AE8: =+MIN(AE9+AE10,Global!AE81) -> 12.856375 | AF8: =+MIN(AF9+AF10,Global!AF81) -> 6.4281875 | AG8: =+MIN(AG9+AG10,Global!AG81) -> 3.2140937 | AH8: =+MIN(AH9+AH10,Global!AH81) -> 1.6070469 | ... BI8: =+MIN(BI9+BI10,Global!BI81) -> 1.1973432e-08
A9: Carbon tax for Hotelling rents | B9: 0 | C9: =+Global!C84 -> 3.0070389e-21 | D9: =+Global!D84 -> 5.2132334e-17 | E9: =+Global!E84 -> 2.15492e-14 | F9: =+Global!F84 -> 1.7689817e-12 | G9: =+Global!G84 -> 5.7664278e-11 | H9: =+Global!H84 -> 1.008745e-09 | I9: =+Global!I84 -> 1.1392095e-08 | J9: =+Global!J84 -> 9.4039466e-08 | ... BI9: =+Global!BI84 -> 18.344415
A10: GLOBAL | B10: 0.001 | C10: 0.001 | D10: 0.001 | E10: 0.001 | F10: 0.001 | G10: 0.001 | H10: 0.001 | I10: 0.001 | J10: 0.001 | K10: 0.001 | L10: 0.001 | M10: 0.001 | N10: 0.001 | O10: 0.001 | P10: 0.001 | Q10: 0.001 | R10: 0.001 | S10: 0.001 | T10: 0.001 | U10: 0.001 | V10: 0.001 | W10: 0.001 | X10: 0.001 | Y10: 0.001 | Z10: 0.001 | AA10: 0.001 | AB10: 1200 | AC10: 1200 | AD10: 1200 | AE10: 1200 | AF10: 1200 | AG10: 1200 | AH10: 1200 | AI10: 1200 | AJ10: 1200 | AK10: 1200 | AL10: 1200 | AM10: 1200 | AN10: 1200 | AO10: 1200 | AP10: 1200 | AQ10: 1200 | AR10: 1200 | AS10: 1200 | AT10: 1200 | AU10: 1200 | AV10: 1200 | AW10: 1200 | AX10: 1200 | AY10: 1200 | AZ10: 1200 | BA10: 1200 | BB10: 1200 | BC10: 1200 | BD10: 1200 | BE10: 1200 | BF10: 1200 | BG10: 1200 | BH10: 1200 | BI10: 1200
A11: US | B11: =+B$10 -> 0.001 | C11: =+C$10 -> 0.001 | D11: =+D$10 -> 0.001 | E11: =+E$10 -> 0.001 | F11: =+F$10 -> 0.001 | G11: =+G$10 -> 0.001 | H11: =+H$10 -> 0.001 | I11: =+I$10 -> 0.001 | ... BI11: =+BI$10 -> 1200
A12: EU | B12: =+B$10 -> 0.001 | C12: =+C$10 -> 0.001 | D12: =+D$10 -> 0.001 | E12: =+E$10 -> 0.001 | F12: =+F$10 -> 0.001 | G12: =+G$10 -> 0.001 | H12: =+H$10 -> 0.001 | I12: =+I$10 -> 0.001 | ... BI12: =+BI$10 -> 1200
A13: Japan | B13: =+B$10 -> 0.001 | C13: =+C$10 -> 0.001 | D13: =+D$10 -> 0.001 | E13: =+E$10 -> 0.001 | F13: =+F$10 -> 0.001 | G13: =+G$10 -> 0.001 | H13: =+H$10 -> 0.001 | I13: =+I$10 -> 0.001 | ... BI13: =+BI$10 -> 1200
A14: Russia | B14: =+B$10 -> 0.001 | C14: =+C$10 -> 0.001 | D14: =+D$10 -> 0.001 | E14: =+E$10 -> 0.001 | F14: =+F$10 -> 0.001 | G14: =+G$10 -> 0.001 | H14: =+H$10 -> 0.001 | I14: =+I$10 -> 0.001 | ... BI14: =+BI$10 -> 1200
A15: Eurasia | B15: =+B$10 -> 0.001 | C15: =+C$10 -> 0.001 | D15: =+D$10 -> 0.001 | E15: =+E$10 -> 0.001 | F15: =+F$10 -> 0.001 | G15: =+G$10 -> 0.001 | H15: =+H$10 -> 0.001 | I15: =+I$10 -> 0.001 | ... BI15: =+BI$10 -> 1200
A16: China | B16: =+B$10 -> 0.001 | C16: =+C$10 -> 0.001 | D16: =+D$10 -> 0.001 | E16: =+E$10 -> 0.001 | F16: =+F$10 -> 0.001 | G16: =+G$10 -> 0.001 | H16: =+H$10 -> 0.001 | I16: =+I$10 -> 0.001 | ... BI16: =+BI$10 -> 1200
A17: India | B17: =+B$10 -> 0.001 | C17: =+C$10 -> 0.001 | D17: =+D$10 -> 0.001 | E17: =+E$10 -> 0.001 | F17: =+F$10 -> 0.001 | G17: =+G$10 -> 0.001 | H17: =+H$10 -> 0.001 | I17: =+I$10 -> 0.001 | ... BI17: =+BI$10 -> 1200
A18: Middle East | B18: =+B$10 -> 0.001 | C18: =+C$10 -> 0.001 | D18: =+D$10 -> 0.001 | E18: =+E$10 -> 0.001 | F18: =+F$10 -> 0.001 | G18: =+G$10 -> 0.001 | H18: =+H$10 -> 0.001 | I18: =+I$10 -> 0.001 | ... BI18: =+BI$10 -> 1200
A19: Africa | B19: =+B$10 -> 0.001 | C19: =+C$10 -> 0.001 | D19: =+D$10 -> 0.001 | E19: =+E$10 -> 0.001 | F19: =+F$10 -> 0.001 | G19: =+G$10 -> 0.001 | H19: =+H$10 -> 0.001 | I19: =+I$10 -> 0.001 | ... BI19: =+BI$10 -> 1200
A20: Latin America | B20: =+B$10 -> 0.001 | C20: =+C$10 -> 0.001 | D20: =+D$10 -> 0.001 | E20: =+E$10 -> 0.001 | F20: =+F$10 -> 0.001 | G20: =+G$10 -> 0.001 | H20: =+H$10 -> 0.001 | I20: =+I$10 -> 0.001 | ... BI20: =+BI$10 -> 1200
A21: OHI | B21: =+B$10 -> 0.001 | C21: =+C$10 -> 0.001 | D21: =+D$10 -> 0.001 | E21: =+E$10 -> 0.001 | F21: =+F$10 -> 0.001 | G21: =+G$10 -> 0.001 | H21: =+H$10 -> 0.001 | I21: =+I$10 -> 0.001 | ... BI21: =+BI$10 -> 1200
A22: Other | B22: =+B$10 -> 0.001 | C22: =+C$10 -> 0.001 | D22: =+D$10 -> 0.001 | E22: =+E$10 -> 0.001 | F22: =+F$10 -> 0.001 | G22: =+G$10 -> 0.001 | H22: =+H$10 -> 0.001 | I22: =+I$10 -> 0.001 | ... BI22: =+BI$10 -> 1200
A23: Emissions wtd tax | B23: =+SUMPRODUCT(Controls!B11:B22*Data!$C$89:$C$100)/SUM(Data!$C$89:$C$100) -> 0.001 | C23: =+SUMPRODUCT(Controls!C11:C22*Data!$C$89:$C$100)/SUM(Data!$C$89:$C$100) -> 0.001 | D23: =+SUMPRODUCT(Controls!D11:D22*Data!$C$89:$C$100)/SUM(Data!$C$89:$C$100) -> 0.001 | E23: =+SUMPRODUCT(Controls!E11:E22*Data!$C$89:$C$100)/SUM(Data!$C$89:$C$100) -> 0.001 | F23: =+SUMPRODUCT(Controls!F11:F22*Data!$C$89:$C$100)/SUM(Data!$C$89:$C$100) -> 0.001 | G23: =+SUMPRODUCT(Controls!G11:G22*Data!$C$89:$C$100)/SUM(Data!$C$89:$C$100) -> 0.001 | H23: =+SUMPRODUCT(Controls!H11:H22*Data!$C$89:$C$100)/SUM(Data!$C$89:$C$100) -> 0.001 | I23: =+SUMPRODUCT(Controls!I11:I22*Data!$C$89:$C$100)/SUM(Data!$C$89:$C$100) -> 0.001 | ... M23: =+SUMPRODUCT(Controls!M11:M22*Data!$C$89:$C$100)/SUM(Data!$C$89:$C$100) -> 0.001
A24: Note: The GLOBAL figure is control variable for optimal runs.
B26: 2005 | C26: 2015 | D26: 2025 | E26: 2035 | F26: 2045 | G26: 2055 | H26: 2065 | I26: 2075 | J26: 2085 | K26: 2095 | L26: 2105 | M26: 2115 | N26: 2125 | O26: 2135 | P26: 2145 | Q26: 2155 | R26: 2165 | S26: 2175 | T26: 2185 | U26: 2195 | V26: 2205 | W26: 2215 | X26: 2225 | Y26: 2235 | Z26: 2245 | AA26: 2255 | AB26: 2265 | AC26: 2275 | AD26: 2285 | AE26: 2295 | AF26: 2305 | AG26: 2315 | AH26: 2325 | AI26: 2335 | AJ26: 2345 | AK26: 2355 | AL26: 2365 | AM26: 2375 | AN26: 2385 | AO26: 2395 | AP26: 2405 | AQ26: 2415 | AR26: 2425 | AS26: 2435 | AT26: 2445 | AU26: 2455 | AV26: 2465 | AW26: 2475 | AX26: 2485 | AY26: 2495 | AZ26: 2505 | BA26: 2515 | BB26: 2525 | BC26: 2535 | BD26: 2545 | BE26: 2555 | BF26: 2565 | BG26: 2575 | BH26: 2585 | BI26: 2595
A27: SAVINGS RATE | B27: 0.17851792 | C27: 0.20440907 | D27: 0.20081284 | E27: 0.19862437 | F27: 0.19724537 | G27: 0.19749783 | H27: 0.19980406
A28: US | B28: 0.17851792 | C28: 0.20441169 | D28: 0.20081131 | E28: 0.19862348 | F28: 0.19724518 | G28: 0.19749773 | H28: 0.19978659 | I28: 0.20224864 | J28: 0.20500133 | K28: 0.20701315 | L28: 0.20687069 | M28: 0.22030308 | N28: =+M28 -> 0.22030308 | O28: =+N28 -> 0.22030308 | P28: =+O28 -> 0.22030308 | Q28: =+P28 -> 0.22030308 | R28: =+Q28 -> 0.22030308 | S28: =+R28 -> 0.22030308 | T28: =+S28 -> 0.22030308 | U28: =+T28 -> 0.22030308 | ... BI28: =+BH28 -> 0.22030308
A29: EU | B29: 0.17464279 | C29: 0.19951188 | D29: 0.19621703 | E29: 0.19444765 | F29: 0.1931177 | G29: 0.19342038 | H29: 0.19499882 | I29: 0.19675156 | J29: 0.19867754 | K29: 0.20517685 | L29: 0.21074493 | M29: 0.22033628 | N29: =+M29 -> 0.22033628 | O29: =+N29 -> 0.22033628 | P29: =+O29 -> 0.22033628 | Q29: =+P29 -> 0.22033628 | R29: =+Q29 -> 0.22033628 | S29: =+R29 -> 0.22033628 | T29: =+S29 -> 0.22033628 | U29: =+T29 -> 0.22033628 | ... BI29: =+BH29 -> 0.22033628
A30: Japan | B30: 0.15130517 | C30: 0.1802888 | D30: 0.17561051 | E30: 0.1683494 | F30: 0.17936265 | G30: 0.18715053 | H30: 0.18886752 | I30: 0.19078953 | J30: 0.19299544 | K30: 0.20201478 | L30: 0.20937149 | M30: 0.22226937 | N30: =+M30 -> 0.22226937 | O30: =+N30 -> 0.22226937 | P30: =+O30 -> 0.22226937 | Q30: =+P30 -> 0.22226937 | R30: =+Q30 -> 0.22226937 | S30: =+R30 -> 0.22226937 | T30: =+S30 -> 0.22226937 | U30: =+T30 -> 0.22226937 | ... BI30: =+BH30 -> 0.22226937
A31: Russia | B31: 0.1911687 | C31: 0.18903154 | D31: 0.18513371 | E31: 0.18556387 | F31: 0.18787393 | G31: 0.18989119 | H31: 0.19064813 | I31: 0.1916834 | J31: 0.1930806 | K31: 0.2031348 | L31: 0.21241991 | M31: 0.22223323 | N31: =+M31 -> 0.22223323 | O31: =+N31 -> 0.22223323 | P31: =+O31 -> 0.22223323 | Q31: =+P31 -> 0.22223323 | R31: =+Q31 -> 0.22223323 | S31: =+R31 -> 0.22223323 | T31: =+S31 -> 0.22223323 | U31: =+T31 -> 0.22223323 | ... BI31: =+BH31 -> 0.22223323
A32: Eurasia | B32: 0.19500684 | C32: 0.22579566 | D32: 0.21818997 | E32: 0.2137652 | F32: 0.21103997 | G32: 0.21054286 | H32: 0.21015163 | I32: 0.21016396 | J32: 0.21067751 | K32: 0.21679425 | L32: 0.22273955 | M32: 0.22890899 | N32: =+M32 -> 0.22890899 | O32: =+N32 -> 0.22890899 | P32: =+O32 -> 0.22890899 | Q32: =+P32 -> 0.22890899 | R32: =+Q32 -> 0.22890899 | S32: =+R32 -> 0.22890899 | T32: =+S32 -> 0.22890899 | U32: =+T32 -> 0.22890899 | ... BI32: =+BH32 -> 0.22890899
A33: China | B33: 0.35708144 | C33: 0.22676101 | D33: 0.21516476 | E33: 0.20754873 | F33: 0.20327969 | G33: 0.20375853 | H33: 0.20342374 | I33: 0.20334247 | J33: 0.2031673 | K33: 0.20922027 | L33: 0.21852012 | M33: 0.21324434 | N33: =+M33 -> 0.21324434 | O33: =+N33 -> 0.21324434 | P33: =+O33 -> 0.21324434 | Q33: =+P33 -> 0.21324434 | R33: =+Q33 -> 0.21324434 | S33: =+R33 -> 0.21324434 | T33: =+S33 -> 0.21324434 | U33: =+T33 -> 0.21324434 | ... BI33: =+BH33 -> 0.21324434
A34: India | B34: 0.29484649 | C34: 0.26865631 | D34: 0.25373354 | E34: 0.24344426 | F34: 0.23218357 | G34: 0.22645882 | H34: 0.22526328 | I34: 0.22454207 | J34: 0.22439286 | K34: 0.22474462 | L34: 0.22572862 | M34: 0.22819109 | N34: =+M34 -> 0.22819109 | O34: =+N34 -> 0.22819109 | P34: =+O34 -> 0.22819109 | Q34: =+P34 -> 0.22819109 | R34: =+Q34 -> 0.22819109 | S34: =+R34 -> 0.22819109 | T34: =+S34 -> 0.22819109 | U34: =+T34 -> 0.22819109 | ... BI34: =+BH34 -> 0.22819109
A35: Middle East | B35: 0.25700191 | C35: 0.25015233 | D35: 0.23912168 | E35: 0.23072693 | F35: 0.22098173 | G35: 0.21762884 | H35: 0.21845421 | I35: 0.21955434 | J35: 0.22101455 | K35: 0.21586229 | L35: 0.20942697 | M35: 0.21875519 | N35: =+M35 -> 0.21875519 | O35: =+N35 -> 0.21875519 | P35: =+O35 -> 0.21875519 | Q35: =+P35 -> 0.21875519 | R35: =+Q35 -> 0.21875519 | S35: =+R35 -> 0.21875519 | T35: =+S35 -> 0.21875519 | U35: =+T35 -> 0.21875519 | ... BI35: =+BH35 -> 0.21875519
A36: Africa | B36: 0.29788861 | C36: 0.30359078 | D36: 0.28874203 | E36: 0.27593629 | F36: 0.2561328 | G36: 0.24401481 | H36: 0.24256581 | I36: 0.24152834 | J36: 0.24092325 | K36: 0.23202159 | L36: 0.22490583 | M36: 0.22378232 | N36: =+M36 -> 0.22378232 | O36: =+N36 -> 0.22378232 | P36: =+O36 -> 0.22378232 | Q36: =+P36 -> 0.22378232 | R36: =+Q36 -> 0.22378232 | S36: =+R36 -> 0.22378232 | T36: =+S36 -> 0.22378232 | U36: =+T36 -> 0.22378232 | ... BI36: =+BH36 -> 0.22378232
A37: Latin America | B37: 0.23570389 | C37: 0.23790902 | D37: 0.2291227 | E37: 0.22069702 | F37: 0.21416108 | G37: 0.21272082 | H37: 0.21309604 | I37: 0.21378594 | J37: 0.21491052 | K37: 0.21680028 | L37: 0.21764557 | M37: 0.22618787 | N37: =+M37 -> 0.22618787 | O37: =+N37 -> 0.22618787 | P37: =+O37 -> 0.22618787 | Q37: =+P37 -> 0.22618787 | R37: =+Q37 -> 0.22618787 | S37: =+R37 -> 0.22618787 | T37: =+S37 -> 0.22618787 | U37: =+T37 -> 0.22618787 | ... BI37: =+BH37 -> 0.22618787
A38: OHI | B38: 0.18690855 | C38: 0.20306632 | D38: 0.19794957 | E38: 0.19302618 | F38: 0.18994992 | G38: 0.18934598 | H38: 0.19102341 | I38: 0.19285652 | J38: 0.19479925 | K38: 0.20167915 | L38: 0.20770716 | M38: 0.2169109 | N38: =+M38 -> 0.2169109 | O38: =+N38 -> 0.2169109 | P38: =+O38 -> 0.2169109 | Q38: =+P38 -> 0.2169109 | R38: =+Q38 -> 0.2169109 | S38: =+R38 -> 0.2169109 | T38: =+S38 -> 0.2169109 | U38: =+T38 -> 0.2169109 | ... BI38: =+BH38 -> 0.2169109
A39: Other | B39: 0.24090678 | C39: 0.27878901 | D39: 0.26593413 | E39: 0.254325 | F39: 0.24142114 | G39: 0.23453135 | H39: 0.23295199 | I39: 0.2318317 | J39: 0.23124471 | K39: 0.22879017 | L39: 0.22945447 | M39: 0.22371271 | N39: =+M39 -> 0.22371271 | O39: =+N39 -> 0.22371271 | P39: =+O39 -> 0.22371271 | Q39: =+P39 -> 0.22371271 | R39: =+Q39 -> 0.22371271 | S39: =+R39 -> 0.22371271 | T39: =+S39 -> 0.22371271 | U39: =+T39 -> 0.22371271 | ... BI39: =+BH39 -> 0.22371271
A41: Note: Shaded values are optimized. First period is given, and later periods are held constant at last period.
B43: 2005 | C43: 2015 | D43: 2025 | E43: 2035 | F43: 2045 | G43: 2055 | H43: 2065 | I43: 2075 | J43: 2085 | K43: 2095 | L43: 2105 | M43: 2115 | N43: 2125 | O43: 2135 | P43: 2145 | Q43: 2155 | R43: 2165 | S43: 2175 | T43: 2185 | U43: 2195 | V43: 2205 | W43: 2215 | X43: 2225 | Y43: 2235 | Z43: 2245 | AA43: 2255 | AB43: 2265 | AC43: 2275 | AD43: 2285 | AE43: 2295 | AF43: 2305 | AG43: 2315 | AH43: 2325 | AI43: 2335 | AJ43: 2345 | AK43: 2355 | AL43: 2365 | AM43: 2375 | AN43: 2385 | AO43: 2395 | AP43: 2405 | AQ43: 2415 | AR43: 2425 | AS43: 2435 | AT43: 2445 | AU43: 2455 | AV43: 2465 | AW43: 2475 | AX43: 2485 | AY43: 2495 | AZ43: 2505 | BA43: 2515 | BB43: 2525 | BC43: 2535 | BD43: 2545 | BE43: 2555 | BF43: 2565 | BG43: 2575 | BH43: 2585 | BI43: 2595
A44: PARTICIPATION RATES
...

Sheet Parameters
A2: Linked Parameters | B2: are linked files between this and other sheets (base, opt, …)
B3: are damage control parameters that must be carefully examined.
B6: Parameter value | D6: Notes
A8: KEY PARAMETERS
A9: Rate of social time preference (% py) | B9: 0.015 | D9: This parameter is part of the calibration for the real interest rate. It should be adjusted along with the EMUC
A10: Elasticity of MU of consumption (set) | B10: 1.5 | D10: This parameter is part of the calibration for the real interest rate. It should be adjusted along with the EMUC
A11: Damage coefficient on temperature | B11: 0.0017543802 | D11: Damage coefficients are calibrated to impact analysis and should be adjusted together
A12: Damage coefficient on temperature squared | B12: 0.0022592108 | D12: Damage coefficients are calibrated to impact analysis and should be adjusted together
A13: Exponent on damages | B13: 2 | D13: Damage coefficients are calibrated to impact analysis and should be adjusted together
A14: Price backstop technology (2005 US 000 $ per tC) | B14: 1.2 | D14: See A Question of Balance for discussion. This parameter also affects the abatement costs.
A15: Exponent of control cost function | B15: 2.8 | D15: See A Question of Balance for discussion. This parameter also affects the abatement costs.
A16: Backstop inflection year | B16: 2250 | D16: Backstop price and abatement costs fall rapidly after this year.
A17: Maximum carbon resources (GtC) | B17: 6000 | D17: See A Question of Balance for discussion.
A18: Equilibrium temperature increase for CO2 doubling | B18: 3.2 | D18: Updated from IPCC FAR, median of models, Table 8.2.
A19: Decline rate TFP (per decade) | B19: 0.1 | D19: This parameter is part of the long-run productivity growth assumptions. It generally does not need adjustment
A20: TFP convergence rate (per decade) | B20: 0.1 | D20: This parameter is part of the long-run productivity growth assumptions. It generally does not need adjustment
... A32: Exponent for catastrophic damages | B32: 6 | D32: Not used
A33: Damage rate at threshold for catastrophic damages | B33: =+A6 -> 0 | D33: Not used
A34: OUTPUT and PRODUCTION
A35: Capital share | C35: 0.3 | D35: assumed | F35: 0.3 | G35: 0.3 | H35: 0.3 | I35: 0.3 | J35: 0.3 | K35: 0.3 | L35: 0.3 | M35: 0.3 | N35: 0.3 | O35: 0.3 | P35: 0.3 | Q35: 0.3 | R35: Data
A36: Rate of depreciation (percent per year) | C36: 0.1 | D36: assumed | F36: 0.1 | G36: 0.1 | H36: 0.1 | I36: 0.1 | J36: 0.1 | K36: 0.1 | L36: 0.1 | M36: 0.1 | N36: 0.1 | O36: 0.1 | P36: 0.1 | Q36: 0.1 | R36: Data
A37: Initial output (2005 US International $, trillions) | C37: 55.34 | D37: data | E37: =SUM(F37:Q37) -> 55.378946 | F37: =+Data!C140 -> 12.3979 | G37: =+Data!D140 -> 13.031057 | H37: =+Data!E140 -> 3.8702838 | I37: =+Data!F140 -> 1.6979567 | J37: =+Data!G140 -> 0.80733505 | K37: =+Data!H140 -> 5.3332327 | L37: =+Data!I140 -> 2.4408315 | M37: =+Data!J140 -> 3.4801033 | ... Q37: =+Data!N140 -> 2.6191887
A38: Initial real interest rate (percent per decade annualized) | C38: 0.05 | D38: calibrated | F38: =+Data!C142 -> 0.062765473 | G38: =+Data!D142 -> 0.067765473 | H38: =+Data!E142 -> 0.062765473 | I38: =+Data!F142 -> 0.082765473 | J38: =+Data!G142 -> 0.077765473 | K38: =+Data!H142 -> 0.072765473 | L38: =+Data!I142 -> 0.077765473 | M38: =+Data!J142 -> 0.092765473 | ... Q38: =+Data!N142 -> 0.077765473 | R38: This is fundamental for calculation of the discount rate.
A39: Initial K | C39: 180 | D39: calculated | F39: =+Data!C143 -> 22.8511 | G39: =+Data!D143 -> 23.302275 | H39: =+Data!E143 -> 7.1334855 | I39: =+Data!F143 -> 2.7871074 | J39: =+Data!G143 -> 1.3624722 | K39: =+Data!H143 -> 9.260935 | L39: =+Data!I143 -> 4.1191883 | M39: =+Data!J143 -> 5.4160685 | ... Q39: =+Data!N143 -> 4.4201869 | R39: From production function
A40: Calculated A | D40: calculated | F40: =+Data!C144 -> 11.347695 | G40: =+Data!D144 -> 8.3478215 | H40: =+Data!E144 -> 9.0624352 | I40: =+Data!F144 -> 4.8677308 | J40: =+Data!G144 -> 2.7019694 | K40: =+Data!H144 -> 2.2708227 | L40: =+Data!I144 -> 1.498374 | M40: =+Data!J144 -> 3.8948608 | ... Q40: =+Data!N144 -> 1.7549043 | R40: From production function
A41: Initial savings rate | D41: calculated | F41: =+Data!C145 -> 0.23181398 | G41: =+Data!D145 -> 0.21696963 | H41: =+Data!E145 -> 0.21278717 | I41: =+Data!F145 -> 0.20100021 | J41: =+Data!G145 -> 0.20828063 | K41: =+Data!H145 -> 0.3110511 | L41: =+Data!I145 -> 0.27229998 | M41: =+Data!J145 -> 0.225188 | ... Q41: =+Data!N145 -> 0.24387583
A42: WELFARE
A43: Rate of social time preference (% py) | C43: 0.015 | D43: calibrated | F43: =+$C43 -> 0.015 | G43: =+$C43 -> 0.015 | H43: =+$C43 -> 0.015 | I43: =+$C43 -> 0.015 | J43: =+$C43 -> 0.015 | K43: =+$C43 -> 0.015 | L43: =+$C43 -> 0.015 | M43: =+$C43 -> 0.015 | ... Q43: =+$C43 -> 0.015 | R43: A fundamental assumption.
A44: Decline of rate of time preference (% per decade) | C44: 0 | D44: assumed | F44: =+$C44 -> 0 | G44: =+$C44 -> 0 | H44: =+$C44 -> 0 | I44: =+$C44 -> 0 | J44: =+$C44 -> 0 | K44: =+$C44 -> 0 | L44: =+$C44 -> 0 | M44: =+$C44 -> 0 | ... Q44: =+$C44 -> 0
A45: Elasticity of MU of consumption (set) | C45: =+B10 -> 1.5 | D45: calibrated | F45: =+$C45 -> 1.5 | G45: =+$C45 -> 1.5 | H45: =+$C45 -> 1.5 | I45: =+$C45 -> 1.5 | J45: =+$C45 -> 1.5 | K45: =+$C45 -> 1.5 | L45: =+$C45 -> 1.5 | M45: =+$C45 -> 1.5 | ... Q45: =+$C45 -> 1.5 | R45: This is calculated from Ramsey equation and data are RSTP and real interest rate, population growth, and p.c. consumption.
A46: Elasticity of MU of consumption (calibrated) | D46: NA
A47: POPULATION
A48: Initial population (millions) | D48: data | E48: =SUM(F48:Q48) -> 6410.8916 | F48: =+Data!C141 -> 296.84258 | G48: =+Data!D141 -> 490.08019 | H48: =+Data!E141 -> 127.773 | I48: =+Data!F141 -> 143.15 | J48: =+Data!G141 -> 155.94247 | K48: =+Data!H141 -> 1304.5 | L48: =+Data!I141 -> 1094.583 | M48: =+Data!J141 -> 412.769 | ... Q48: =+Data!N141 -> 937.19557 | R48: Data
C49: Global | F49: US | G49: EU | H49: Japan | I49: Russia | J49: Eurasia | K49: China | L49: India | M49: Middle East | N49: Africa | O49: Latin America | P49: OHI | Q49: Other non-OECD Asia
A50: DAMAGE FUNCTION | B50: If individual country damages = 1, otherwise 0 | J50: 1
A51: damage coefficient on temperature | C51: =+B11 -> 0.0017543802 | D51: DICE 2007 | F51: =IF($J$50=0,$C51,F119) -> 0 | G51: =IF($J$50=0,$C51,G119) -> 0 | H51: =IF($J$50=0,$C51,H119) -> 0 | I51: =IF($J$50=0,$C51,I119) -> 0 | J51: =IF($J$50=0,$C51,J119) -> 0 | K51: =IF($J$50=0,$C51,K119) -> 0.078458281 | L51: =IF($J$50=0,$C51,L119) -> 0.43852128 | M51: =IF($J$50=0,$C51,M119) -> 0.27798926 | ... Q51: =IF($J$50=0,$C51,Q119) -> 0.17551223 | R51: These three parameters are fundamental for optimization, but not for basic calculations of paths
A52: damage coefficient on temperature squared | C52: =+B12 -> 0.0022592108 | D52: DICE 2007 | F52: =IF($J$50=0,$C52,F120) -> 0.14141261 | G52: =IF($J$50=0,$C52,G120) -> 0.15910847 | H52: =IF($J$50=0,$C52,H120) -> 0.16172344 | I52: =IF($J$50=0,$C52,I120) -> 0.11505844 | J52: =IF($J$50=0,$C52,J120) -> 0.13047244 | K52: =IF($J$50=0,$C52,K120) -> 0.12589303 | L52: =IF($J$50=0,$C52,L120) -> 0.16887308 | M52: =IF($J$50=0,$C52,M120) -> 0.15859856 | ... Q52: =IF($J$50=0,$C52,Q120) -> 0.17344211 | R52: Ditto
A53: Exponent on damages | C53: =+B13 -> 2 | D53: DICE 2007 | F53: =IF($J$50=0,$C53,F121) -> 2 | G53: =IF($J$50=0,$C53,G121) -> 2 | H53: =IF($J$50=0,$C53,H121) -> 2 | I53: =IF($J$50=0,$C53,I121) -> 2 | J53: =IF($J$50=0,$C53,J121) -> 2 | K53: =IF($J$50=0,$C53,K121) -> 2 | L53: =IF($J$50=0,$C53,L121) -> 2 | M53: =IF($J$50=0,$C53,M121) -> 2 | ... Q53: =IF($J$50=0,$C53,Q121) -> 2 | R53: Ditto
A54: Threshold for catastrophic damages | C54: =+B31 -> 4 | D54: assumed | F54: =IF($J$50=0,$C54,F122) -> 4 | G54: =IF($J$50=0,$C54,G122) -> 4 | H54: =IF($J$50=0,$C54,H122) -> 4 | I54: =IF($J$50=0,$C54,I122) -> 4 | J54: =IF($J$50=0,$C54,J122) -> 4 | K54: =IF($J$50=0,$C54,K122) -> 4 | L54: =IF($J$50=0,$C54,L122) -> 4 | M54: =IF($J$50=0,$C54,M122) -> 4 | ... Q54: =IF($J$50=0,$C54,Q122) -> 4
A55: Exponent for catastrophic damages | C55: =+B32 -> 6 | D55: assumed | F55: =IF($J$50=0,$C55,F123) -> 6 | G55: =IF($J$50=0,$C55,G123) -> 6 | H55: =IF($J$50=0,$C55,H123) -> 6 | I55: =IF($J$50=0,$C55,I123) -> 6 | J55: =IF($J$50=0,$C55,J123) -> 6 | K55: =IF($J$50=0,$C55,K123) -> 6 | L55: =IF($J$50=0,$C55,L123) -> 6 | M55: =IF($J$50=0,$C55,M123) -> 6 | ... Q55: =IF($J$50=0,$C55,Q123) -> 6
...

Sheet Data
F1: =+E4 -> 0.015093183 | G1: =+F4 -> 0 | I1: =+Parameters!B19 -> 0.1 | L1: =+Parameters!B21 -> 0.0033 | N1: =+F1+G1 -> 0.015093183 | O1: =+$L$1+(1-$I$1)*(N1-$L$1) -> 0.013913865 | P1: =+$L$1+(1-$I$1)*(O1-$L$1) -> 0.012852479
M2: 0 | N2: 1 | O2: 2 | P2: 3 | Q2: 4 | R2: =+Q2+1 -> 5 | S2: =+R2+1 -> 6 | T2: =+S2+1 -> 7 | U2: =+T2+1 -> 8 | V2: =+U2+1 -> 9 | W2: =+V2+1 -> 10 | X2: =+W2+1 -> 11 | Y2: =+X2+1 -> 12 | ... BT2: =+BS2+1 -> 59 | BU2: 2005 | BV2: 2100 | BW2: 2200 | BX2: 2300
E3: average 95-15 | F3: adjustment | G3: Sum | H3: Sum minus long | I3: Decline rate TFP | J3: Converge ratio | K3: Converge rate | L3: Long run' | M3: 2005 | N3: =+M3+10 -> 2015 | O3: =+N3+10 -> 2025 | P3: =+O3+10 -> 2035 | Q3: =+P3+10 -> 2045 | R3: =+Q3+10 -> 2055 | S3: =+R3+10 -> 2065 | T3: =+S3+10 -> 2075 | U3: =+T3+10 -> 2085 | ... BT3: =+BS3+10 -> 2595
C4: US | E4: =+AVERAGE(E21:F21) -> 0.015093183 | F4: =+Parameters!B24 -> 0 | G4: =+E4+F4 -> 0.015093183 | H4: =+G4-L4 -> 0.011793183 | I4: =+I1 -> 0.1 | L4: =+L1 -> 0.0033 | M4: =+F108*1000 -> 41765.909 | N4: =+M4*EXP(10*(G4)) -> 48570.302 | O4: =+N4*EXP(10*$L4)*EXP(10*$H4*EXP(-$I4*(O$2-1))) -> 55852.898 | P4: =+O4*EXP(10*$L4)*EXP(10*$H4*EXP(-$I4*(P$2-1))) -> 63578.53 | Q4: =+P4*EXP(10*$L4)*EXP(10*$H4*EXP(-$I4*(Q$2-1))) -> 71710.837 | R4: =+Q4*EXP(10*$L4)*EXP(10*$H4*EXP(-$I4*(R$2-1))) -> 80213.67 | S4: =+R4*EXP(10*$L4)*EXP(10*$H4*EXP(-$I4*(S$2-1))) -> 89052.246 | T4: =+S4*EXP(10*$L4)*EXP(10*$H4*EXP(-$I4*(T$2-1))) -> 98194.047 | U4: =+T4*EXP(10*$L4)*EXP(10*$H4*EXP(-$I4*(U$2-1))) -> 107609.49 | V4: =+U4*EXP(10*$L4)*EXP(10*$H4*EXP(-$I4*(V$2-1))) -> 117272.35 | ... BT4: =+BS4*EXP(10*$L4)*EXP(10*$H4*EXP(-$I4*(BT$2-1))) -> 1007223.1 | BU4: =+M4/M$4 -> 1 | BV4: =+V4/V$4 -> 1 | BW4: =+AG4/AG$4 -> 1 | BX4: =+AQ4/AQ$4 -> 1 | BZ4: =+J4 -> 0
C5: OECD-Europe | E5: =+AVERAGE(E22:F22) -> 0.014299541 | F5: 0.002 | G5: =+E5+F5 -> 0.016299541 | H5: =+G5-L5 -> 0.012999541 | J5: =+MAX(J22+Parameters!$B$30,0.1) -> 0.9 | K5: =+Parameters!B20 -> 0.1 | L5: =+L4 -> 0.0033 | M5: =+F109*1000 -> 26589.643 | N5: =+M5*EXP(10*(G5)) -> 31296.842 | O5: =+N5*(O$4/N$4)*(N$4*$J5/N5)^$K5 -> 37212.316 | P5: =+O5*(P$4/O$4)*(O$4*$J5/O5)^$K5 -> 43652.752 | Q5: =+P5*(Q$4/P$4)*(P$4*$J5/P5)^$K5 -> 50587.134 | R5: =+Q5*(R$4/Q$4)*(Q$4*$J5/Q5)^$K5 -> 57980.558 | S5: =+R5*(S$4/R$4)*(R$4*$J5/R5)^$K5 -> 65796.036 | T5: =+S5*(T$4/S$4)*(S$4*$J5/S5)^$K5 -> 73996.091 | U5: =+T5*(U$4/T$4)*(T$4*$J5/T5)^$K5 -> 82544.106 | V5: =+U5*(V$4/U$4)*(U$4*$J5/U5)^$K5 -> 91405.396 | ... BT5: =+BS5*(BT$4/BS$4)*(BS$4*$J5/BS5)^$K5 -> 905829.04 | BU5: =+M5/M$4 -> 0.63663508 | BV5: =+V5/V$4 -> 0.77942837 | BW5: =+AG5/AG$4 -> 0.86028019 | BX5: =+AQ5/AQ$4 -> 0.88594653 | BZ5: =+J5 -> 0.9
C6: Japan | E6: =+AVERAGE(E23:F23) -> 0.010784143 | F6: 0.003 | G6: =+E6+F6 -> 0.013784143 | H6: =+G6-L6 -> 0.010484143 | J6: 0.9 | K6: =+K5 -> 0.1 | L6: =+L5 -> 0.0033 | M6: =+F110*1000 -> 30290.31 | N6: =+M6*EXP(10*(G6)) -> 34767.022 | O6: =+N6*(O$4/N$4)*(N$4*$J6/N6)^$K6 -> 40905.997 | P6: =+O6*(P$4/O$4)*(O$4*$J6/O6)^$K6 -> 47533.728 | Q6: =+P6*(Q$4/P$4)*(P$4*$J6/P6)^$K6 -> 54617.435 | R6: =+Q6*(R$4/Q$4)*(Q$4*$J6/Q6)^$K6 -> 62121.866 | S6: =+R6*(S$4/R$4)*(R$4*$J6/R6)^$K6 -> 70010.894 | T6: =+S6*(T$4/S$4)*(S$4*$J6/S6)^$K6 -> 78248.871 | U6: =+T6*(U$4/T$4)*(T$4*$J6/T6)^$K6 -> 86801.742 | V6: =+U6*(V$4/U$4)*(U$4*$J6/U6)^$K6 -> 95637.886 | ... BT6: =+BS6*(BT$4/BS$4)*(BS$4*$J6/BS6)^$K6 -> 906040.38 | BU6: =+M6/M$4 -> 0.72524005 | BV6: =+V6/V$4 -> 0.81551949 | BW6: =+AG6/AG$4 -> 0.87258723 | BX6: =+AQ6/AQ$4 -> 0.89034533 | BZ6: =+J6 -> 0.9
C7: Russia | E7: =+AVERAGE(E24:F24) -> 0.040982313 | F7: -0.015 | G7: =+E7+F7 -> 0.025982313 | H7: =+G7-L7 -> 0.022682313 | J7: 0.6 | K7: =+K6 -> 0.1 | L7: =+L6 -> 0.0033 | M7: =+F111*1000 -> 11861.381 | N7: =+M7*EXP(10*(G7)) -> 15380.661 | O7: =+N7*(O$4/N$4)*(N$4*$J7/N7)^$K7 -> 18854.049 | P7: =+O7*(P$4/O$4)*(O$4*$J7/O7)^$K7 -> 22732.575 | Q7: =+P7*(Q$4/P$4)*(P$4*$J7/P7)^$K7 -> 27002.517 | R7: =+Q7*(R$4/Q$4)*(Q$4*$J7/Q7)^$K7 -> 31644.703 | S7: =+R7*(S$4/R$4)*(R$4*$J7/R7)^$K7 -> 36635.943 | T7: =+S7*(T$4/S$4)*(S$4*$J7/S7)^$K7 -> 41950.441 | U7: =+T7*(U$4/T$4)*(T$4*$J7/T7)^$K7 -> 47561.103 | V7: =+U7*(V$4/U$4)*(U$4*$J7/U7)^$K7 -> 53440.679 | ... BT7: =+BS7*(BT$4/BS$4)*(BS$4*$J7/BS7)^$K7 -> 603477.62 | BU7: =+M7/M$4 -> 0.28399671 | BV7: =+V7/V$4 -> 0.45569719 | BW7: =+AG7/AG$4 -> 0.55037508 | BX7: =+AQ7/AQ$4 -> 0.58220835 | BZ7: =+J7 -> 0.6
C8: Non-Russia Eurasia | E8: =+AVERAGE(E25:F25) -> 0.03969822 | F8: -0.015 | G8: =+E8+F8 -> 0.02469822 | H8: =+G8-L8 -> 0.02139822 | J8: =+MAX(J25+Parameters!$B$30,0.1) -> 0.6 | K8: =+K7 -> 0.1 | L8: =+L7 -> 0.0033 | M8: =+F112*1000 -> 5177.134 | N8: =+M8*EXP(10*(G8)) -> 6627.5408 | O8: =+N8*(O$4/N$4)*(N$4*$J8/N8)^$K8 -> 8837.8023 | P8: =+O8*(P$4/O$4)*(O$4*$J8/O8)^$K8 -> 11494.612 | Q8: =+P8*(Q$4/P$4)*(P$4*$J8/P8)^$K8 -> 14617.24 | R8: =+Q8*(R$4/Q$4)*(Q$4*$J8/Q8)^$K8 -> 18214.449 | S8: =+R8*(S$4/R$4)*(R$4*$J8/R8)^$K8 -> 22284.91 | T8: =+S8*(T$4/S$4)*(S$4*$J8/S8)^$K8 -> 26818.204 | U8: =+T8*(U$4/T$4)*(T$4*$J8/T8)^$K8 -> 31796.24 | V8: =+U8*(V$4/U$4)*(U$4*$J8/U8)^$K8 -> 37194.903 | ... BT8: =+BS8*(BT$4/BS$4)*(BS$4*$J8/BS8)^$K8 -> 602351.54 | BU8: =+M8/M$4 -> 0.12395597 | BV8: =+V8/V$4 -> 0.31716686 | BW8: =+AG8/AG$4 -> 0.49121155 | BX8: =+AQ8/AQ$4 -> 0.55957349 | BZ8: =+J8 -> 0.6
C9: China | E9: =+AVERAGE(E26:F26) -> 0.081398792 | F9: -0.01 | G9: =+E9+F9 -> 0.071398792 | H9: =+G9-L9 -> 0.068098792 | J9: 0.6 | K9: =+K8 -> 0.1 | L9: =+L8 -> 0.0033 | M9: =+F113*1000 -> 4088.3348 | N9: =+M9*EXP(10*(G9)) -> 8348.8656 | O9: =+N9*(O$4/N$4)*(N$4*$J9/N9)^$K9 -> 10879.072 | P9: =+O9*(P$4/O$4)*(O$4*$J9/O9)^$K9 -> 13858.528 | Q9: =+P9*(Q$4/P$4)*(P$4*$J9/P9)^$K9 -> 17296.805 | R9: =+Q9*(R$4/Q$4)*(Q$4*$J9/Q9)^$K9 -> 21193.686 | S9: =+R9*(S$4/R$4)*(R$4*$J9/R9)^$K9 -> 25540.083 | T9: =+S9*(T$4/S$4)*(S$4*$J9/S9)^$K9 -> 30319.356 | U9: =+T9*(U$4/T$4)*(T$4*$J9/T9)^$K9 -> 35508.883 | V9: =+U9*(V$4/U$4)*(U$4*$J9/U9)^$K9 -> 41081.714 | ... BT9: =+BS9*(BT$4/BS$4)*(BS$4*$J9/BS9)^$K9 -> 602660.17 | BU9: =+M9/M$4 -> 0.097886886 | BV9: =+V9/V$4 -> 0.35031032 | BW9: =+AG9/AG$4 -> 0.5067739 | BX9: =+AQ9/AQ$4 -> 0.56569223 | BZ9: =+J9 -> 0.6
C10: India | E10: =+AVERAGE(E27:F27) -> 0.050495488 | F10: -0.005 | G10: =+E10+F10 -> 0.045495488 | H10: =+G10-L10 -> 0.042195488 | J10: 0.5 | K10: =+K9 -> 0.1 | L10: =+L9 -> 0.0033 | M10: =+F114*1000 -> 2229.9191 | N10: =+M10*EXP(10*(G10)) -> 3514.5805 | O10: =+N10*(O$4/N$4)*(N$4*$J10/N10)^$K10 -> 4903.3753 | P10: =+O10*(P$4/O$4)*(O$4*$J10/O10)^$K10 -> 6642.2002 | Q10: =+P10*(Q$4/P$4)*(P$4*$J10/P10)^$K10 -> 8761.594 | R10: =+Q10*(R$4/Q$4)*(Q$4*$J10/Q10)^$K10 -> 11283.501 | S10: =+R10*(S$4/R$4)*(R$4*$J10/R10)^$K10 -> 14220.597 | T10: =+S10*(T$4/S$4)*(S$4*$J10/S10)^$K10 -> 17576.314 | U10: =+T10*(U$4/T$4)*(T$4*$J10/T10)^$K10 -> 21345.481 | V10: =+U10*(V$4/U$4)*(U$4*$J10/U10)^$K10 -> 25515.405 | ... BT10: =+BS10*(BT$4/BS$4)*(BS$4*$J10/BS10)^$K10 -> 501456.53 | BU10: =+M10/M$4 -> 0.05339089 | BV10: =+V10/V$4 -> 0.21757393 | BW10: =+AG10/AG$4 -> 0.38509725 | BX10: =+AQ10/AQ$4 -> 0.45648868 | BZ10: =+J10 -> 0.5
C11: Middle East | E11: =+AVERAGE(E28:F28) -> 0.023533797 | F11: 0 | G11: =+E11+F11 -> 0.023533797 | H11: =+G11-L11 -> 0.020233797 | J11: 0.5 | K11: =+K10 -> 0.1 | L11: =+L10 -> 0.0033 | M11: =+F115*1000 -> 8431.116 | N11: =+M11*EXP(10*(G11)) -> 10668.198 | O11: =+N11*(O$4/N$4)*(N$4*$J11/N11)^$K11 -> 13319.592 | P11: =+O11*(P$4/O$4)*(O$4*$J11/O11)^$K11 -> 16327.067 | Q11: =+P11*(Q$4/P$4)*(P$4*$J11/P11)^$K11 -> 19684.289 | R11: =+Q11*(R$4/Q$4)*(Q$4*$J11/Q11)^$K11 -> 23379.048 | S11: =+R11*(S$4/R$4)*(R$4*$J11/R11)^$K11 -> 27394.443 | T11: =+S11*(T$4/S$4)*(S$4*$J11/S11)^$K11 -> 31710.128 | U11: =+T11*(U$4/T$4)*(T$4*$J11/T11)^$K11 -> 36303.551 | V11: =+U11*(V$4/U$4)*(U$4*$J11/U11)^$K11 -> 41151.088 | ... BT11: =+BS11*(BT$4/BS$4)*(BS$4*$J11/BS11)^$K11 -> 502693.31 | BU11: =+M11/M$4 -> 0.20186598 | BV11: =+V11/V$4 -> 0.35090188 | BW11: =+AG11/AG$4 -> 0.44741533 | BX11: =+AQ11/AQ$4 -> 0.48099779 | BZ11: =+J11 -> 0.5
C12: Africa | E12: =+AVERAGE(E29:F29) -> 0.026482695 | F12: 0.01 | G12: =+E12+F12 -> 0.036482695 | H12: =+G12-L12 -> 0.033182695 | J12: 0.4 | K12: =+K11 -> 0.1 | L12: =+L11 -> 0.0033 | M12: =+F116*1000 -> 1703.3657 | N12: =+M12*EXP(10*(G12)) -> 2453.2976 | O12: =+N12*(O$4/N$4)*(N$4*$J12/N12)^$K12 -> 3469.7102 | P12: =+O12*(P$4/O$4)*(O$4*$J12/O12)^$K12 -> 4758.1619 | Q12: =+P12*(Q$4/P$4)*(P$4*$J12/P12)^$K12 -> 6346.0963 | R12: =+Q12*(R$4/Q$4)*(Q$4*$J12/Q12)^$K12 -> 8254.3725 | S12: =+R12*(S$4/R$4)*(R$4*$J12/R12)^$K12 -> 10496.463 | T12: =+S12*(T$4/S$4)*(S$4*$J12/S12)^$K12 -> 13078.245 | U12: =+T12*(U$4/T$4)*(T$4*$J12/T12)^$K12 -> 15998.322 | V12: =+U12*(V$4/U$4)*(U$4*$J12/U12)^$K12 -> 19248.775 | ... BT12: =+BS12*(BT$4/BS$4)*(BS$4*$J12/BS12)^$K12 -> 401043.89 | BU12: =+M12/M$4 -> 0.040783638 | BV12: =+V12/V$4 -> 0.16413737 | BW12: =+AG12/AG$4 -> 0.30245556 | BX12: =+AQ12/AQ$4 -> 0.36285322 | BZ12: =+J12 -> 0.4
C13: Latin America | E13: =+AVERAGE(E30:F30) -> 0.01926661 | F13: 0.01 | G13: =+E13+F13 -> 0.02926661 | H13: =+G13-L13 -> 0.02596661 | J13: 0.7 | K13: =+K12 -> 0.1 | L13: =+L12 -> 0.0033 | M13: =+F117*1000 -> 8207.8498 | N13: =+M13*EXP(10*(G13)) -> 10998.48 | O13: =+N13*(O$4/N$4)*(N$4*$J13/N13)^$K13 -> 14158.629 | P13: =+O13*(P$4/O$4)*(O$4*$J13/O13)^$K13 -> 17840.138 | Q13: =+P13*(Q$4/P$4)*(P$4*$J13/P13)^$K13 -> 22048.221 | R13: =+Q13*(R$4/Q$4)*(Q$4*$J13/Q13)^$K13 -> 26777.38 | S13: =+R13*(S$4/R$4)*(R$4*$J13/R13)^$K13 -> 32012.708 | T13: =+S13*(T$4/S$4)*(S$4*$J13/S13)^$K13 -> 37731.558 | U13: =+T13*(U$4/T$4)*(T$4*$J13/T13)^$K13 -> 43905.405 | V13: =+U13*(V$4/U$4)*(U$4*$J13/U13)^$K13 -> 50501.713 | ... BT13: =+BS13*(BT$4/BS$4)*(BS$4*$J13/BS13)^$K13 -> 703293.05 | BU13: =+M13/M$4 -> 0.19652032 | BV13: =+V13/V$4 -> 0.43063616 | BW13: =+AG13/AG$4 -> 0.6010186 | BX13: =+AQ13/AQ$4 -> 0.6637614 | BZ13: =+J13 -> 0.7
C14: OHI | E14: =+AVERAGE(E31:F31) -> 0.023825929 | F14: -0.005 | G14: =+E14+F14 -> 0.018825929 | H14: =+G14-L14 -> 0.015525929 | J14: 0.9 | K14: =+K13 -> 0.1 | L14: =+L13 -> 0.0033 | M14: =+F118*1000 -> 29744.22 | N14: =+M14*EXP(10*(G14)) -> 35905.631 | O14: =+N14*(O$4/N$4)*(N$4*$J14/N14)^$K14 -> 42109.738 | P14: =+O14*(P$4/O$4)*(O$4*$J14/O14)^$K14 -> 48790.793 | Q14: =+P14*(Q$4/P$4)*(P$4*$J14/P14)^$K14 -> 55915.692 | R14: =+Q14*(R$4/Q$4)*(Q$4*$J14/Q14)^$K14 -> 63449.274 | S14: =+R14*(S$4/R$4)*(R$4*$J14/R14)^$K14 -> 71355.848 | T14: =+S14*(T$4/S$4)*(S$4*$J14/S14)^$K14 -> 79600.471 | U14: =+T14*(U$4/T$4)*(T$4*$J14/T14)^$K14 -> 88149.984 | V14: =+U14*(V$4/U$4)*(U$4*$J14/U14)^$K14 -> 96973.794 | ... BT14: =+BS14*(BT$4/BS$4)*(BS$4*$J14/BS14)^$K14 -> 906105.16 | BU14: =+M14/M$4 -> 0.71216503 | BV14: =+V14/V$4 -> 0.82691099 | BW14: =+AG14/AG$4 -> 0.87639397 | BX14: =+AQ14/AQ$4 -> 0.89169775 | BZ14: =+J14 -> 0.9
C15: Other non-OECD Asia | E15: =+AVERAGE(E32:F32) -> 0.027948055 | F15: 0 | G15: =+E15+F15 -> 0.027948055 | H15: =+G15-L15 -> 0.024648055 | J15: 0.6 | K15: =+K14 -> 0.1 | L15: =+L14 -> 0.0033 | M15: =+F119*1000 -> 2794.7088 | N15: =+M15*EXP(10*(G15)) -> 3695.8423 | O15: =+N15*(O$4/N$4)*(N$4*$J15/N15)^$K15 -> 5224.7943 | P15: =+O15*(P$4/O$4)*(O$4*$J15/O15)^$K15 -> 7162.2049 | Q15: =+P15*(Q$4/P$4)*(P$4*$J15/P15)^$K15 -> 9549.1025 | R15: =+Q15*(R$4/Q$4)*(Q$4*$J15/Q15)^$K15 -> 12416.623 | S15: =+R15*(S$4/R$4)*(R$4*$J15/R15)^$K15 -> 15784.819 | T15: =+S15*(T$4/S$4)*(S$4*$J15/S15)^$K15 -> 19662.355 | U15: =+T15*(U$4/T$4)*(T$4*$J15/T15)^$K15 -> 24047.007 | V15: =+U15*(V$4/U$4)*(U$4*$J15/U15)^$K15 -> 28926.785 | ... BT15: =+BS15*(BT$4/BS$4)*(BS$4*$J15/BS15)^$K15 -> 601571.59 | BU15: =+M15/M$4 -> 0.066913636 | BV15: =+V15/V$4 -> 0.2466633 | BW15: =+AG15/AG$4 -> 0.45394758 | BX15: =+AQ15/AQ$4 -> 0.54439034 | BZ15: =+J15 -> 0.6
C16: World | J16: =+AVERAGE(J5:J15) -> 0.65454545 | L16: World (2005 pop wt) | M16: =+SUMPRODUCT(M4:M15*$A$21:$A32)/SUM($A$21:$A$32) -> 8638.2595 | N16: =+SUMPRODUCT(N4:N15*$A$21:$A32)/SUM($A$21:$A$32) -> 11333.513 | O16: =+SUMPRODUCT(O4:O15*$A$21:$A32)/SUM($A$21:$A$32) -> 14042.617 | P16: =+SUMPRODUCT(P4:P15*$A$21:$A32)/SUM($A$21:$A$32) -> 17163.006 | Q16: =+SUMPRODUCT(Q4:Q15*$A$21:$A32)/SUM($A$21:$A$32) -> 20705.938 | R16: =+SUMPRODUCT(R4:R15*$A$21:$A32)/SUM($A$21:$A$32) -> 24674.922 | S16: =+SUMPRODUCT(S4:S15*$A$21:$A32)/SUM($A$21:$A$32) -> 29066 | T16: =+SUMPRODUCT(T4:T15*$A$21:$A32)/SUM($A$21:$A$32) -> 33868.454 | ... BT16: =+SUMPRODUCT(BT4:BT15*$A$21:$A32)/SUM($A$21:$A$32) -> 617571.07
J17: =+STDEV(J5:J15) -> 0.17529196
E18: [macro_072309.xlsx]newpcGDP'!E38 | M18: TFP
E19: p.c. GDP growth from data and IMF projections
A20: Population 2005 | E20: 1995-05 | F20: 2005-2015 | N20: 21c | O20: 22c
A21: 296.84258 | C21: US | E21: 0.021372937 | F21: 0.0088134301 | M21: US | N21: =+LN(W4/M4)/100 -> 0.011133661 | O21: =+LN(AG4/W4)/100 -> 0.0061818427 | P21: =+LN(AQ4/AG4)/100 -> 0.0043601707
A22: 490.08019 | C22: OECD-Europe | E22: 0.019405919 | F22: 0.0091931642 | J22: 0.9 | M22: OECD-Europe | N22: =+LN(W5/M5)/100 -> 0.013301136 | O22: =+LN(AG5/W5)/100 -> 0.0070249822 | P22: =+LN(AQ5/AG5)/100 -> 0.0046541552
A23: 127.773 | C23: Japan | E23: 0.0094777509 | F23: 0.012090535 | J23: 0.85 | M23: Japan | N23: =+LN(W6/M6)/100 -> 0.012405456 | O23: =+LN(AG6/W6)/100 -> 0.0067596463 | P23: =+LN(AQ6/AG6)/100 -> 0.0045616383
A24: 143.15 | C24: Russia | E24: 0.041235271 | F24: 0.040729354 | J24: 0.5 | M24: Russia | N24: =+LN(W7/M7)/100 -> 0.01613742 | O24: =+LN(AG7/W7)/100 -> 0.0077944564 | P24: =+LN(AQ7/AG7)/100 -> 0.0049224543
A25: 155.94247 | C25: Non-Russia Eurasia | E25: 0.038240844 | F25: 0.041155595 | J25: 0.6 | M25: Non-Russia Eurasia | N25: =+LN(W8/M8)/100 -> 0.021166178 | O25: =+LN(AG8/W8)/100 -> 0.0099188097 | P25: =+LN(AQ8/AG8)/100 -> 0.0056631705
A26: 1304.5 | C26: China | E26: 0.079109032 | F26: 0.083688552 | J26: 0.5 | M26: China | N26: =+LN(W9/M9)/100 -> 0.024421839 | O26: =+LN(AG9/W9)/100 -> 0.009336188 | P26: =+LN(AQ9/AG9)/100 -> 0.0054600229
A27: 1094.583 | C27: India | E27: 0.04589835 | F27: 0.055092625 | J27: 0.4 | M27: India | N27: =+LN(W10/M10)/100 -> 0.026014716 | O27: =+LN(AG10/W10)/100 -> 0.011059345 | P27: =+LN(AQ10/AG10)/100 -> 0.0060608507
A28: 412.769 | C28: Middle East | E28: 0.021206492 | F28: 0.025861103 | J28: 0.4 | M28: Middle East | N28: =+LN(W11/M11)/100 -> 0.017016789 | O28: =+LN(AG11/W11)/100 -> 0.0082575479 | P28: =+LN(AQ11/AG11)/100 -> 0.0050839243
A29: 763.50611 | C29: Africa | E29: 0.021621116 | F29: 0.031344274 | J29: 0.35 | M29: Africa | N29: =+LN(W12/M12)/100 -> 0.025948649 | O29: =+LN(AG12/W12)/100 -> 0.011403388 | P29: =+LN(AQ12/AG12)/100 -> 0.0061808111
A30: 555.38008 | C30: Latin America | E30: 0.013704364 | F30: 0.024828856 | J30: 0.5 | M30: Latin America | N30: =+LN(W13/M13)/100 -> 0.019464455 | O30: =+LN(AG13/W13)/100 -> 0.0090296492 | P30: =+LN(AQ13/AG13)/100 -> 0.0053531394
A31: 129.16962 | C31: OHI | E31: 0.028315553 | F31: 0.019336306 | J31: 0.85 | M31: OHI | N31: =+LN(W14/M14)/100 -> 0.012712232 | O31: =+LN(AG14/W14)/100 -> 0.0066783317 | P31: =+LN(AQ14/AG14)/100 -> 0.0045332857
A32: 937.19557 | C32: Other non-OECD Asia | E32: 0.020751458 | F32: 0.035144651 | J32: 0.5 | M32: Other non-OECD Asia | N32: =+LN(W15/M15)/100 -> 0.025068781 | O32: =+LN(AG15/W15)/100 -> 0.011392512 | P32: =+LN(AQ15/AG15)/100 -> 0.0061770187
A33: 6418.8626 | C33: World | M33: World
D34: =+LN(Parameters!B27)/20 -> 0 | E34: =+LN(Parameters!B27) -> 0
A36: Populati0n growth with uncertainty
A37: Population growth projections (Mark) | B37: 2015 | C37: 2025 | D37: 2035 | E37: 2045 | F37: 2055 | G37: 2065 | H37: 2075 | I37: 2085 | J37: 2095 | K37: 2105 | L37: 2115 | M37: 2125 | N37: 2135 | O37: 2145 | P37: 2155 | Q37: 2165 | R37: 2175 | S37: 2185 | T37: 2195 | U37: 2205 | V37: 2215 | W37: 2225 | X37: 2235 | Y37: 2245 | Z37: 2255 | AA37: 2265 | AB37: 2275 | AC37: 2285 | AD37: 2295 | AE37: 2305
A38: US | B38: =+B375 -> 0.0093279314 | C38: =+C375+LN(Parameters!$B$27)/200 -> 0.0076456914 | D38: =+D375+LN(Parameters!$B$27)/200 -> 0.0057596483 | E38: =+E375+LN(Parameters!$B$27)/200 -> 0.0043177913 | F38: =+F375+LN(Parameters!$B$27)/200 -> 0.0024627299 | G38: =+G375+LN(Parameters!$B$27)/200 -> 0.0013456355 | H38: =+H375+LN(Parameters!$B$27)/200 -> 0.0013456355 | I38: =+I375+LN(Parameters!$B$27)/200 -> 0.0013456355 | J38: =+J375+LN(Parameters!$B$27)/200 -> 0.0013456355 | ... V38: =+V375+LN(Parameters!$B$27)/200 -> 0.00047770103 | W38: 0.00047770103 | X38: 0.00047770103 | Y38: 0.00047770103 | Z38: 0.00047770103 | AA38: 0.00047770103 | AB38: 0.00047770103 | AC38: 0.00047770103 | AD38: 0.00047770103 | AE38: 0.00023885051
A39: OECD-Europe | B39: =+B376 -> 0.0043457149 | C39: =+C376+LN(Parameters!$B$27)/200 -> 0.0023580396 | D39: =+D376+LN(Parameters!$B$27)/200 -> 0.00096646886 | E39: =+E376+LN(Parameters!$B$27)/200 -> -1.0403662e-06 | F39: =+F376+LN(Parameters!$B$27)/200 -> -0.001550573 | G39: =+G376+LN(Parameters!$B$27)/200 -> -0.0023819981 | H39: =+H376+LN(Parameters!$B$27)/200 -> -0.0023819981 | I39: =+I376+LN(Parameters!$B$27)/200 -> -0.0023819981 | J39: =+J376+LN(Parameters!$B$27)/200 -> -0.0023819981 | ... V39: =+V376+LN(Parameters!$B$27)/200 -> 0.00062793446 | W39: 0.00062793446 | X39: 0.00062793446 | Y39: 0.00062793446 | Z39: 0.00062793446 | AA39: 0.00062793446 | AB39: 0.00062793446 | AC39: 0.00062793446 | AD39: 0.00062793446 | AE39: 0.00031396723
A40: Japan | B40: =+B377 -> -0.0013094485 | C40: =+C377+LN(Parameters!$B$27)/200 -> -0.0040543463 | D40: =+D377+LN(Parameters!$B$27)/200 -> -0.0060224741 | E40: =+E377+LN(Parameters!$B$27)/200 -> -0.0072870345 | F40: =+F377+LN(Parameters!$B$27)/200 -> -0.005930006 | G40: =+G377+LN(Parameters!$B$27)/200 -> -0.0039881769 | H40: =+H377+LN(Parameters!$B$27)/200 -> -0.0039881769 | I40: =+I377+LN(Parameters!$B$27)/200 -> -0.0039881769 | J40: =+J377+LN(Parameters!$B$27)/200 -> -0.0039881769 | ... V40: =+V377+LN(Parameters!$B$27)/200 -> 0.00061680665 | W40: 0.00061680665 | X40: 0.00061680665 | Y40: 0.00061680665 | Z40: 0.00061680665 | AA40: 0.00061680665 | AB40: 0.00061680665 | AC40: 0.00061680665 | AD40: 0.00061680665 | AE40: 0.00030840333
A41: Russia | B41: =+B378 -> -0.0036902246 | C41: =+C378+LN(Parameters!$B$27)/200 -> -0.004171834 | D41: =+D378+LN(Parameters!$B$27)/200 -> -0.0054007195 | E41: =+E378+LN(Parameters!$B$27)/200 -> -0.0051458271 | F41: =+F378+LN(Parameters!$B$27)/200 -> -0.0049860706 | G41: =+G378+LN(Parameters!$B$27)/200 -> -0.0048680141 | H41: =+H378+LN(Parameters!$B$27)/200 -> -0.0048680141 | I41: =+I378+LN(Parameters!$B$27)/200 -> -0.0048680141 | J41: =+J378+LN(Parameters!$B$27)/200 -> -0.0048680141 | ... V41: =+V378+LN(Parameters!$B$27)/200 -> 0.00054989085 | W41: 0.00054989085 | X41: 0.00054989085 | Y41: 0.00054989085 | Z41: 0.00054989085 | AA41: 0.00054989085 | AB41: 0.00054989085 | AC41: 0.00054989085 | AD41: 0.00054989085 | AE41: 0.00027494543
...

Sheet Copen
A1: This is a calculation of emissions limits by regions | BR1: NEW BASELINE
BS2: 2005 | BT2: =+BS2+10 -> 2015 | BU2: =+BT2+10 -> 2025 | BV2: =+BU2+10 -> 2035 | BW2: =+BV2+10 -> 2045 | BX2: =+BW2+10 -> 2055 | BY2: =+BX2+10 -> 2065 | BZ2: =+BY2+10 -> 2075 | CA2: =+BZ2+10 -> 2085 | ... DZ2: =+DY2+10 -> 2595
A3: Baseline industrial emissions | C3: 1990 | D3: 1991 | E3: 1992 | F3: 1993 | G3: 1994 | H3: 1995 | I3: 1996 | J3: 1997 | K3: 1998 | L3: 1999 | M3: 2000 | N3: 2001 | O3: 2002 | P3: 2003 | Q3: 2004 | R3: 2005 | S3: 2006 | T3: 2007 | U3: 2008 | V3: 2009 | W3: 2010 | X3: 2015 | Y3: 2020 | Z3: 2025 | AA3: =+Z3+5 -> 2030 | AB3: =+AA3+5 -> 2035 | AC3: =+AB3+5 -> 2040 | AD3: =+AC3+5 -> 2045 | AE3: =+AD3+5 -> 2050 | AF3: =+AE3+5 -> 2055 | AG3: =+AF3+5 -> 2060 | AH3: =+AG3+5 -> 2065 | ... BL3: =+BK3+5 -> 2215 | BR3: US | BS3: =+BS22*BS35 -> 1.6621335 | BT3: =+BT22*BT35 -> 1.623889 | BU3: =+BU22*BU35 -> 1.7936993 | BV3: =+BV22*BV35 -> 1.9159712 | BW3: =+BW22*BW35 -> 2.0064006 | BX3: =+BX22*BX35 -> 2.0633899 | BY3: =+BY22*BY35 -> 2.0996013 | BZ3: =+BZ22*BZ35 -> 2.1359058 | ... DZ3: =+DZ22*DZ35 -> 3.566312
A4: US | B4: CO2 | C4: 1.3721369 | D4: 1.3594361 | E4: 1.3862585 | F4: 1.4163666 | G4: 1.4379934 | H4: 1.4532129 | I4: 1.5042551 | J4: 1.5262424 | K4: 1.5337064 | L4: 1.5508817 | M4: 1.5993053 | N4: 1572.6163 | O4: 1589.1217 | P4: 1603.9216 | Q4: 1628.7599 | R4: =+Data!F89/1000 -> 1.6621335 | S4: 1.6242076 | T4: =+S4*($X4/$S4)^(0.111111111111111) -> 1.6241722 | U4: =+T4*($X4/$S4)^(0.111111111111111) -> 1.6241368 | V4: =+U4*($X4/$S4)^(0.111111111111111) -> 1.6241014 | W4: =+V4*($X4/$S4)^(0.111111111111111) -> 1.624066 | X4: =+BT3 -> 1.623889 | Y4: =+(X4*Z4)^0.5 -> 1.7066835 | Z4: =+BU3 -> 1.7936993 | AA4: =+(Z4*AB4)^0.5 -> 1.8538274 | AB4: =+BV3 -> 1.9159712 | AC4: =+(AB4*AD4)^0.5 -> 1.9606646 | AD4: =+BW3 -> 2.0064006 | AE4: =+(AD4*AF4)^0.5 -> 2.0346958 | AF4: =+BX3 -> 2.0633899 | AG4: =+(AF4*AH4)^0.5 -> 2.0814169 | AH4: =+BY3 -> 2.0996013 | AI4: =+(AH4*AJ4)^0.5 -> 2.1176757 | AJ4: =+BZ3 -> 2.1359058 | AK4: =+(AJ4*AL4)^0.5 -> 2.1548765 | AL4: =+CA3 -> 2.1740157 | AM4: =+(AL4*AN4)^0.5 -> 2.1944381 | AN4: =+CB3 -> 2.2150523 | AO4: =+(AN4*AP4)^0.5 -> 2.2340551 | AP4: =+CC3 -> 2.2532209 | AQ4: =+(AP4*AR4)^0.5 -> 2.2694385 | AR4: =+CD3 -> 2.2857729 | AS4: =+(AR4*AT4)^0.5 -> 2.3009849 | AT4: =+CE3 -> 2.3162981 | AU4: =+(AT4*AV4)^0.5 -> 2.3415799 | AV4: =+CF3 -> 2.3671376 | AW4: =+(AV4*AX4)^0.5 -> 2.386809 | AX4: =+CG3 -> 2.4066439 | AY4: =+(AX4*AZ4)^0.5 -> 2.423671 | AZ4: =+CH3 -> 2.4408186 | BA4: =+(AZ4*BB4)^0.5 -> 2.4567258 | BB4: =+CI3 -> 2.4727368 | BC4: =+(BB4*BD4)^0.5 -> 2.4883025 | BD4: =+CJ3 -> 2.5039662 | BE4: =+(BD4*BF4)^0.5 -> 2.5195815 | BF4: =+CK3 -> 2.5352941 | BG4: =+(BF4*BH4)^0.5 -> 2.5511487 | BH4: =+CL3 -> 2.5671025 | BI4: =+(BH4*BJ4)^0.5 -> 2.5821675 | BJ4: =+CM3 -> 2.5973209 | BK4: =+(BJ4*BL4)^0.5 -> 2.6113617 | BL4: =+CN3 -> 2.6254785 | BR4: EU | BS4: =+BS23*BS36 -> 1.1460506 | BT4: =+BT23*BT36 -> 0.99417388 | BU4: =+BU23*BU36 -> 1.1065871 | BV4: =+BV23*BV36 -> 1.1896401 | BW4: =+BW23*BW36 -> 1.2528505 | BX4: =+BX23*BX36 -> 1.293256 | BY4: =+BY23*BY36 -> 1.3187353 | BZ4: =+BZ23*BZ36 -> 1.3389633 | ... DZ4: =+DZ23*DZ36 -> 2.627593
A5: EU | B5: CO2 | C5: 1.1330683 | D5: 1.1302015 | E5: 1.1028089 | F5: 1.1073034 | G5: 1.095643 | H5: 1.1089181 | I5: 1.1450598 | J5: 1.1493936 | K5: 1.1496953 | L5: 1.1431401 | M5: 1.158012 | N5: 1170.4459 | O5: 1162.5325 | P5: 1200.1058 | Q5: 1209.0135 | R5: =+Data!F90/1000 -> 1.1460506 | S5: 1.2456868 | T5: =+S5*($X5/$S5)^(0.111111111111111) -> 1.2148591 | U5: =+T5*($X5/$S5)^(0.111111111111111) -> 1.1847943 | V5: =+U5*($X5/$S5)^(0.111111111111111) -> 1.1554736 | W5: =+V5*($X5/$S5)^(0.111111111111111) -> 1.1268784 | X5: =+BT4 -> 0.99417388 | Y5: =+(X5*Z5)^0.5 -> 1.0488756 | Z5: =+BU4 -> 1.1065871 | AA5: =+(Z5*AB5)^0.5 -> 1.1473624 | AB5: =+BV4 -> 1.1896401 | AC5: =+(AB5*AD5)^0.5 -> 1.2208363 | AD5: =+BW4 -> 1.2528505 | AE5: =+(AD5*AF5)^0.5 -> 1.2728929 | AF5: =+BX4 -> 1.293256 | AG5: =+(AF5*AH5)^0.5 -> 1.3059335 | AH5: =+BY4 -> 1.3187353 | AI5: =+(AH5*AJ5)^0.5 -> 1.3288108 | AJ5: =+BZ4 -> 1.3389633 | AK5: =+(AJ5*AL5)^0.5 -> 1.3470843 | AL5: =+CA4 -> 1.3552546 | AM5: =+(AL5*AN5)^0.5 -> 1.3618172 | AN5: =+CB4 -> 1.3684116 | AO5: =+(AN5*AP5)^0.5 -> 1.3836713 | AP5: =+CC4 -> 1.3991011 | AQ5: =+(AP5*AR5)^0.5 -> 1.4231837 | AR5: =+CD4 -> 1.4476807 | AS5: =+(AR5*AT5)^0.5 -> 1.4704785 | AT5: =+CE4 -> 1.4936354 | AU5: =+(AT5*AV5)^0.5 -> 1.5197558 | AV5: =+CF4 -> 1.5463329 | AW5: =+(AV5*AX5)^0.5 -> 1.5689006 | AX5: =+CG4 -> 1.5917976 | AY5: =+(AX5*AZ5)^0.5 -> 1.6121794 | AZ5: =+CH4 -> 1.6328222 | BA5: =+(AZ5*BB5)^0.5 -> 1.6517663 | BB5: =+CI4 -> 1.6709302 | BC5: =+(BB5*BD5)^0.5 -> 1.6888498 | BD5: =+CJ4 -> 1.7069617 | BE5: =+(BD5*BF5)^0.5 -> 1.7240922 | BF5: =+CK4 -> 1.7413946 | BG5: =+(BF5*BH5)^0.5 -> 1.7578759 | BH5: =+CL4 -> 1.7745132 | BI5: =+(BH5*BJ5)^0.5 -> 1.7910236 | BJ5: =+CM4 -> 1.8076877 | BK5: =+(BJ5*BL5)^0.5 -> 1.824441 | BL5: =+CN4 -> 1.8413496 | BN5: These are GDP times baseline sigma. | BR5: Japan | BS5: =+BS24*BS37 -> 0.36996593 | BT5: =+BT24*BT37 -> 0.3821269 | BU5: =+BU24*BU37 -> 0.38413432 | BV5: =+BV24*BV37 -> 0.37226152 | BW5: =+BW24*BW37 -> 0.34678852 | BX5: =+BX24*BX37 -> 0.33340003 | BY5: =+BY24*BY37 -> 0.32645083 | BZ5: =+BZ24*BZ37 -> 0.31908299 | ... DZ5: =+DZ24*DZ37 -> 0.53567144
